Workbook

Sheet README
B2: Remat Al-Riyadh — Data & Analytics KPI Tracker
B3: Production-Grade · Cross-Sheet Dynamic · Dropdown-Driven
B5: Owner: Saad | Reports: Yasir (Data Engineering) · Ahmad (BI)
B7: DATA FLOW (how the workbook is wired)
B8: Lookups → source of all dropdown lists (Tiers, Statuses, Owners, Domains, etc.)
B9: SLA Tiers → KPI × P1/P2/P3 target matrix (single source of truth for Operations targets)
B10: Dashboard Portfolio → master register: tier, owners, stakeholders, governance rules
B11: Ops SLA Tracker → pulls Name/Status/Tier from Portfolio; pulls Targets from SLA Tiers; only Actuals are inputs
B12: Delivery Tracker → 7-stage milestone tracker; computed Delivery KPI Summary at bottom
B13: Scorecard → pulls Operations actuals from Ops SLA Tracker; pulls Delivery actuals from Delivery Tracker
B15: WHAT'S DYNAMIC (and what's input)
B16: INPUTS (yellow cells):
... B47: All lists live in the Lookups sheet — append new options there to extend.

Sheet Scorecard
B2: MONTHLY KPI SCORECARD
B3: Auto-aggregated from Ops SLA Tracker and Delivery Tracker. Targets pull from SLA Tiers (P2 baseline).
B5: Reporting Period: | C5: ='Ops SLA Tracker'!C4 -> MMM-YYYY
B7: # | C7: KPI | D7: Owner | E7: Direction | F7: Target | G7: Weight | H7: Actual | I7: Score | J7: RAG | K7: Source
B8: PILLAR 1 — OPERATIONS (16 live dashboards · pulled from Ops SLA Tracker)
B9: Operations · Data Engineering (Yasir)
B10: 1 | C10: Pipeline availability | D10: Yasir | E10: H | F10: ='SLA Tiers'!D5 -> 0.995 | G10: 0.25 | H10: =IFERROR(AVERAGEIFS('Ops SLA Tracker'!G7:G37,'Ops SLA Tracker'!$D$7:$D$37,"Live"),"") | I10: =IFERROR(IF(H10="","",IF(E10="H",MIN(H10/F10,1.2),IF(AND(E10="L",H10>0),MIN(F10/H10,1.2),""))),"") | J10: =IFERROR(IF(I10="","",IF(I10>=1,"Green",IF(I10>=0.9,"Amber","Red"))),"") | K10: Ops SLA Tracker (Avg, Live)
B11: 2 | C11: Data freshness % met | D11: Yasir | E11: H | F11: ='SLA Tiers'!D6 -> 0.95 | G11: 0.25 | H11: =IFERROR(AVERAGEIFS('Ops SLA Tracker'!J7:J37,'Ops SLA Tracker'!$D$7:$D$37,"Live"),"") | I11: =IFERROR(IF(H11="","",IF(E11="H",MIN(H11/F11,1.2),IF(AND(E11="L",H11>0),MIN(F11/H11,1.2),""))),"") | J11: =IFERROR(IF(I11="","",IF(I11>=1,"Green",IF(I11>=0.9,"Amber","Red"))),"") | K11: Ops SLA Tracker (Avg, Live)
B12: 3 | C12: Pipeline failures / month | D12: Yasir | E12: L | F12: ='SLA Tiers'!D7 -> 2 | G12: 0.15 | H12: =IFERROR(SUMIFS('Ops SLA Tracker'!M7:M37,'Ops SLA Tracker'!$D$7:$D$37,"Live"),"") -> 0 | I12: =IFERROR(IF(H12="","",IF(E12="H",MIN(H12/F12,1.2),IF(AND(E12="L",H12>0),MIN(F12/H12,1.2),""))),"") | J12: =IFERROR(IF(I12="","",IF(I12>=1,"Green",IF(I12>=0.9,"Amber","Red"))),"") | K12: Ops SLA Tracker (Sum, Live)
B13: 4 | C13: Incident MTTR (hours) | D13: Yasir | E13: L | F13: ='SLA Tiers'!D8 -> 4 | G13: 0.15 | H13: =IFERROR(AVERAGEIFS('Ops SLA Tracker'!P7:P37,'Ops SLA Tracker'!$D$7:$D$37,"Live"),"") | I13: =IFERROR(IF(H13="","",IF(E13="H",MIN(H13/F13,1.2),IF(AND(E13="L",H13>0),MIN(F13/H13,1.2),""))),"") | J13: =IFERROR(IF(I13="","",IF(I13>=1,"Green",IF(I13>=0.9,"Amber","Red"))),"") | K13: Ops SLA Tracker (Avg, Live)
B14: 5 | C14: Data quality pass rate | D14: Yasir | E14: H | F14: ='SLA Tiers'!D9 -> 0.98 | G14: 0.2 | H14: =IFERROR(AVERAGEIFS('Ops SLA Tracker'!S7:S37,'Ops SLA Tracker'!$D$7:$D$37,"Live"),"") | I14: =IFERROR(IF(H14="","",IF(E14="H",MIN(H14/F14,1.2),IF(AND(E14="L",H14>0),MIN(F14/H14,1.2),""))),"") | J14: =IFERROR(IF(I14="","",IF(I14>=1,"Green",IF(I14>=0.9,"Amber","Red"))),"") | K14: Ops SLA Tracker (Avg, Live)
C15: Operations · Data Engineering (Yasir) — Weighted Score | I15: =IFERROR(SUMPRODUCT(IF(I10:I14="",0,I10:I14),G10:G14)/SUMPRODUCT(IF(I10:I14="",0,1),G10:G14),"") | J15: =IFERROR(IF(I15="","",IF(I15>=1,"Green",IF(I15>=0.9,"Amber","Red"))),"")
B17: Operations · BI (Ahmad)
B18: 6 | C18: Dashboard availability | D18: Ahmad | E18: H | F18: ='SLA Tiers'!D10 -> 0.995 | G18: 0.25 | H18: =IFERROR(AVERAGEIFS('Ops SLA Tracker'!V7:V37,'Ops SLA Tracker'!$D$7:$D$37,"Live"),"") | I18: =IFERROR(IF(H18="","",IF(E18="H",MIN(H18/F18,1.2),IF(AND(E18="L",H18>0),MIN(F18/H18,1.2),""))),"") | J18: =IFERROR(IF(I18="","",IF(I18>=1,"Green",IF(I18>=0.9,"Amber","Red"))),"") | K18: Ops SLA Tracker (Avg, Live)
B19: 7 | C19: Avg report load time (sec) | D19: Ahmad | E19: L | F19: ='SLA Tiers'!D11 -> 5 | G19: 0.15 | H19: =IFERROR(AVERAGEIFS('Ops SLA Tracker'!Y7:Y37,'Ops SLA Tracker'!$D$7:$D$37,"Live"),"") | I19: =IFERROR(IF(H19="","",IF(E19="H",MIN(H19/F19,1.2),IF(AND(E19="L",H19>0),MIN(F19/H19,1.2),""))),"") | J19: =IFERROR(IF(I19="","",IF(I19>=1,"Green",IF(I19>=0.9,"Amber","Red"))),"") | K19: Ops SLA Tracker (Avg, Live)
B20: 8 | C20: P1 defect resolution (hrs) | D20: Ahmad | E20: L | F20: ='SLA Tiers'!D12 -> 8 | G20: 0.2 | H20: =IFERROR(AVERAGEIFS('Ops SLA Tracker'!AB7:AB37,'Ops SLA Tracker'!$D$7:$D$37,"Live"),"") | I20: =IFERROR(IF(H20="","",IF(E20="H",MIN(H20/F20,1.2),IF(AND(E20="L",H20>0),MIN(F20/H20,1.2),""))),"") | J20: =IFERROR(IF(I20="","",IF(I20>=1,"Green",IF(I20>=0.9,"Amber","Red"))),"") | K20: Ops SLA Tracker (Avg, Live)
B21: 9 | C21: Active user adoption | D21: Ahmad | E21: H | F21: ='SLA Tiers'!D13 -> 0.7 | G21: 0.2 | H21: =IFERROR(AVERAGEIFS('Ops SLA Tracker'!AE7:AE37,'Ops SLA Tracker'!$D$7:$D$37,"Live"),"") | I21: =IFERROR(IF(H21="","",IF(E21="H",MIN(H21/F21,1.2),IF(AND(E21="L",H21>0),MIN(F21/H21,1.2),""))),"") | J21: =IFERROR(IF(I21="","",IF(I21>=1,"Green",IF(I21>=0.9,"Amber","Red"))),"") | K21: Ops SLA Tracker (Avg, Live)
B22: 10 | C22: User CSAT (1-5) | D22: Ahmad | E22: H | F22: ='SLA Tiers'!D14 -> 4 | G22: 0.2 | H22: =IFERROR(AVERAGEIFS('Ops SLA Tracker'!AH7:AH37,'Ops SLA Tracker'!$D$7:$D$37,"Live"),"") | I22: =IFERROR(IF(H22="","",IF(E22="H",MIN(H22/F22,1.2),IF(AND(E22="L",H22>0),MIN(F22/H22,1.2),""))),"") | J22: =IFERROR(IF(I22="","",IF(I22>=1,"Green",IF(I22>=0.9,"Amber","Red"))),"") | K22: Ops SLA Tracker (Avg, Live)
C23: Operations · BI (Ahmad) — Weighted Score | I23: =IFERROR(SUMPRODUCT(IF(I18:I22="",0,I18:I22),G18:G22)/SUMPRODUCT(IF(I18:I22="",0,1),G18:G22),"") | J23: =IFERROR(IF(I23="","",IF(I23>=1,"Green",IF(I23>=0.9,"Amber","Red"))),"")
B26: PILLAR 2 — DELIVERY (15 new dashboards · pulled from Delivery Tracker + manual)
B27: Delivery · Joint
B28: 11 | C28: On-time delivery vs roadmap | D28: Joint | E28: H | F28: 0.9 | G28: 0.3 | H28: ='Delivery Tracker'!T28 | I28: =IFERROR(IF(H28="","",IF(E28="H",MIN(H28/F28,1.2),IF(AND(E28="L",H28>0),MIN(F28/H28,1.2),""))),"") | J28: =IFERROR(IF(I28="","",IF(I28>=1,"Green",IF(I28>=0.9,"Amber","Red"))),"") | K28: Delivery Tracker
B29: 12 | C29: Avg cycle time (days) | D29: Joint | E29: L | F29: 45 | G29: 0.2 | H29: ='Delivery Tracker'!T29 | I29: =IFERROR(IF(H29="","",IF(E29="H",MIN(H29/F29,1.2),IF(AND(E29="L",H29>0),MIN(F29/H29,1.2),""))),"") | J29: =IFERROR(IF(I29="","",IF(I29>=1,"Green",IF(I29>=0.9,"Amber","Red"))),"") | K29: Delivery Tracker
B30: 13 | C30: Estimation accuracy | D30: Joint | E30: H | F30: 0.85 | G30: 0.15 | I30: =IFERROR(IF(H30="","",IF(E30="H",MIN(H30/F30,1.2),IF(AND(E30="L",H30>0),MIN(F30/H30,1.2),""))),"") | J30: =IFERROR(IF(I30="","",IF(I30>=1,"Green",IF(I30>=0.9,"Amber","Red"))),"") | K30: Manual input — from Azure DevOps
B31: 14 | C31: Defect escape rate / dashboard | D31: Joint | E31: L | F31: 2 | G31: 0.15 | I31: =IFERROR(IF(H31="","",IF(E31="H",MIN(H31/F31,1.2),IF(AND(E31="L",H31>0),MIN(F31/H31,1.2),""))),"") | J31: =IFERROR(IF(I31="","",IF(I31>=1,"Green",IF(I31>=0.9,"Amber","Red"))),"") | K31: Manual input — from Azure DevOps
B32: 15 | C32: UAT first-pass rate | D32: Joint | E32: H | F32: 0.8 | G32: 0.2 | H32: ='Delivery Tracker'!T35 -> 0 | I32: =IFERROR(IF(H32="","",IF(E32="H",MIN(H32/F32,1.2),IF(AND(E32="L",H32>0),MIN(F32/H32,1.2),""))),"") -> 0 | J32: =IFERROR(IF(I32="","",IF(I32>=1,"Green",IF(I32>=0.9,"Amber","Red"))),"") -> Red | K32: Delivery Tracker
C33: Delivery · Joint — Weighted Score | I33: =IFERROR(SUMPRODUCT(IF(I28:I32="",0,I28:I32),G28:G32)/SUMPRODUCT(IF(I28:I32="",0,1),G28:G32),"") -> 0 | J33: =IFERROR(IF(I33="","",IF(I33>=1,"Green",IF(I33>=0.9,"Amber","Red"))),"") -> Red
B35: Delivery · Data Engineering (Yasir)
B36: 16 | C36: Fusion semantic-layer coverage | D36: Yasir | E36: H | F36: 0.95 | G36: 0.35 | I36: =IFERROR(IF(H36="","",IF(E36="H",MIN(H36/F36,1.2),IF(AND(E36="L",H36>0),MIN(F36/H36,1.2),""))),"") | J36: =IFERROR(IF(I36="","",IF(I36>=1,"Green",IF(I36>=0.9,"Amber","Red"))),"") | K36: Manual input — from semantic registry
B37: 17 | C37: Pipeline milestone hit rate | D37: Yasir | E37: H | F37: 0.9 | G37: 0.35 | H37: ='Delivery Tracker'!T33 -> 0 | I37: =IFERROR(IF(H37="","",IF(E37="H",MIN(H37/F37,1.2),IF(AND(E37="L",H37>0),MIN(F37/H37,1.2),""))),"") -> 0 | J37: =IFERROR(IF(I37="","",IF(I37>=1,"Green",IF(I37>=0.9,"Amber","Red"))),"") -> Red | K37: Delivery Tracker
B38: 18 | C38: Pre-prod data quality pass rate | D38: Yasir | E38: H | F38: 0.95 | G38: 0.3 | I38: =IFERROR(IF(H38="","",IF(E38="H",MIN(H38/F38,1.2),IF(AND(E38="L",H38>0),MIN(F38/H38,1.2),""))),"") | J38: =IFERROR(IF(I38="","",IF(I38>=1,"Green",IF(I38>=0.9,"Amber","Red"))),"") | K38: Manual input — from DQ framework
C39: Delivery · Data Engineering (Yasir) — Weighted Score | I39: =IFERROR(SUMPRODUCT(IF(I36:I38="",0,I36:I38),G36:G38)/SUMPRODUCT(IF(I36:I38="",0,1),G36:G38),"") -> 0 | J39: =IFERROR(IF(I39="","",IF(I39>=1,"Green",IF(I39>=0.9,"Amber","Red"))),"") -> Red
B41: Delivery · BI (Ahmad)
B42: 19 | C42: Visual milestone hit rate | D42: Ahmad | E42: H | F42: 0.9 | G42: 0.4 | H42: ='Delivery Tracker'!T34 -> 0 | I42: =IFERROR(IF(H42="","",IF(E42="H",MIN(H42/F42,1.2),IF(AND(E42="L",H42>0),MIN(F42/H42,1.2),""))),"") -> 0 | J42: =IFERROR(IF(I42="","",IF(I42>=1,"Green",IF(I42>=0.9,"Amber","Red"))),"") -> Red | K42: Delivery Tracker
B43: 20 | C43: Design review first-pass rate | D43: Ahmad | E43: H | F43: 0.8 | G43: 0.3 | H43: ='Delivery Tracker'!T31 -> 0 | I43: =IFERROR(IF(H43="","",IF(E43="H",MIN(H43/F43,1.2),IF(AND(E43="L",H43>0),MIN(F43/H43,1.2),""))),"") -> 0 | J43: =IFERROR(IF(I43="","",IF(I43>=1,"Green",IF(I43>=0.9,"Amber","Red"))),"") -> Red | K43: Delivery Tracker
B44: 21 | C44: Stakeholder sign-off cycle (days) | D44: Ahmad | E44: L | F44: 5 | G44: 0.3 | H44: ='Delivery Tracker'!T32 -> 9.2222222 | I44: =IFERROR(IF(H44="","",IF(E44="H",MIN(H44/F44,1.2),IF(AND(E44="L",H44>0),MIN(F44/H44,1.2),""))),"") -> 0.54216867 | J44: =IFERROR(IF(I44="","",IF(I44>=1,"Green",IF(I44>=0.9,"Amber","Red"))),"") -> Red | K44: Delivery Tracker
C45: Delivery · BI (Ahmad) — Weighted Score | I45: =IFERROR(SUMPRODUCT(IF(I42:I44="",0,I42:I44),G42:G44)/SUMPRODUCT(IF(I42:I44="",0,1),G42:G44),"") -> 0.1626506 | J45: =IFERROR(IF(I45="","",IF(I45>=1,"Green",IF(I45>=0.9,"Amber","Red"))),"") -> Red
B48: OVERALL ROLE SCORE (60% own-role Ops · 30% own-role Delivery · 10% Joint Delivery)
C49: Yasir — overall score | I49: =IFERROR(I14*0.6 + I38*0.3 + I32*0.1,"") | J49: =IFERROR(IF(I49="","",IF(I49>=1,"Green",IF(I49>=0.9,"Amber","Red"))),"")
C50: Ahmad — overall score | I50: =IFERROR(I22*0.6 + I44*0.3 + I32*0.1,"") | J50: =IFERROR(IF(I50="","",IF(I50>=1,"Green",IF(I50>=0.9,"Amber","Red"))),"")

Sheet Dashboard Portfolio
B2: DASHBOARD PORTFOLIO — Master Register & Stakeholder Governance
B3: Single source of truth for all dashboards. Tier here drives SLA targets in Ops SLA Tracker. Owners, Stakeholders, and Governance Rules captured per dashboard.
B5: ID | C5: Dashboard Name | D5: Domain | E5: Status | F5: Tier | G5: DE Owner | H5: BI Owner | I5: Source System | J5: Refresh Frequency | K5: Refresh Window | L5: Business Sponsor | M5: Data Owner | N5: Change Approver | O5: Escalation Contact | P5: Stakeholder Group | Q5: Access Rule | R5: Change Control Rule | S5: Data Sensitivity | T5: Notes
B6: 1 | C6: Finance — Daily Cash Position | D6: Finance | E6: Live | F6: P1 | G6: Yasir | H6: Ahmad | I6: Oracle Fusion (Finance) | J6: Daily | K6: Daily by 7 AM AST | O6: CFO + Treasury | Q6: View: Department-wide; Edit: D&A team only | R6: Minor: Approver only. Major: Sponsor + Approver. CR via Azure DevOps. | S6: Confidential | T6: Drives daily liquidity decisions
B7: 2 | C7: Finance — AR Aging & Collections | D7: Finance | E7: Live | F7: P2 | G7: Yasir | H7: Ahmad | I7: Oracle Fusion (Finance) | J7: Daily | K7: Daily by 8 AM AST | O7: Finance Dept + Collections | Q7: View: Department-wide; Edit: D&A team only | R7: Minor: Approver only. Major: Sponsor + Approver. CR via Azure DevOps. | S7: Confidential
B8: 3 | C8: Finance — AP Status & Payment Run | D8: Finance | E8: Live | F8: P2 | G8: Yasir | H8: Ahmad | I8: Oracle Fusion (Finance) | J8: Daily | K8: Daily by 8 AM AST | O8: Finance Dept + Treasury | Q8: View: Department-wide; Edit: D&A team only | R8: Minor: Approver only. Major: Sponsor + Approver. CR via Azure DevOps. | S8: Confidential
B9: 4 | C9: Finance — Monthly P&L | D9: Finance | E9: Live | F9: P1 | G9: Yasir | H9: Ahmad | I9: Oracle Fusion (Finance) | J9: Monthly | K9: 5th of month by EOD | O9: CFO + Department Heads | Q9: View: Department-wide; Edit: D&A team only | R9: Minor: Approver only. Major: Sponsor + Approver. CR via Azure DevOps. | S9: Confidential | T9: Used in monthly close
B10: 5 | C10: Finance — Budget vs Actual | D10: Finance | E10: Live | F10: P2 | G10: Yasir | H10: Ahmad | I10: Oracle Fusion (Finance) | J10: Monthly | K10: 5th of month by EOD | O10: Finance Dept + Department Heads | Q10: View: Department-wide; Edit: D&A team only | R10: Minor: Approver only. Major: Sponsor + Approver. CR via Azure DevOps. | S10: Confidential
B11: 6 | C11: Operations — Property Occupancy | D11: Operations | E11: Live | F11: P1 | G11: Yasir | H11: Ahmad | I11: Mixed (Fusion + Manual) | J11: Daily | K11: Daily by 9 AM AST | O11: Operations + Asset Mgmt | Q11: View: Department-wide; Edit: D&A team only | R11: Minor: Approver only. Major: Sponsor + Approver. CR via Azure DevOps. | S11: Internal | T11: Core operational KPI for real estate portfolio
B12: 7 | C12: Operations — Lease Renewals & Expiries | D12: Operations | E12: Live | F12: P2 | G12: Yasir | H12: Ahmad | I12: Mixed (Fusion + Manual) | J12: Weekly | K12: Mondays by 9 AM AST | O12: Asset Mgmt + Leasing | Q12: View: Department-wide; Edit: D&A team only | R12: Minor: Approver only. Major: Sponsor + Approver. CR via Azure DevOps. | S12: Confidential
B13: 8 | C13: Operations — Revenue by Asset | D13: Operations | E13: Live | F13: P1 | G13: Yasir | H13: Ahmad | I13: Oracle Fusion (Finance) | J13: Monthly | K13: 5th of month by EOD | O13: Asset Mgmt + CFO | Q13: View: Department-wide; Edit: D&A team only | R13: Minor: Approver only. Major: Sponsor + Approver. CR via Azure DevOps. | S13: Confidential
B14: 9 | C14: Operations — Maintenance Tickets | D14: Operations | E14: Live | F14: P2 | G14: Yasir | H14: Ahmad | I14: Service Desk Tool | J14: Daily | K14: Daily by 7 AM AST | O14: Operations + Facilities | Q14: View: Department-wide; Edit: D&A team only | R14: Minor: Approver only. Major: Sponsor + Approver. CR via Azure DevOps. | S14: Internal
B15: 10 | C15: HCM — Headcount & Org | D15: HCM | E15: Live | F15: P2 | G15: Yasir | H15: Ahmad | I15: Oracle Fusion (HCM) | J15: Weekly | K15: Mondays by 9 AM AST | O15: HR / People + Department Heads | Q15: View: Department-wide; Edit: D&A team only | R15: Minor: Approver only. Major: Sponsor + Approver. CR via Azure DevOps. | S15: Confidential
B16: 11 | C16: HCM — Attendance & Leave | D16: HCM | E16: Live | F16: P3 | G16: Yasir | H16: Ahmad | I16: Oracle Fusion (HCM) | J16: Weekly | K16: Mondays by 9 AM AST | O16: HR / People | Q16: View: Department-wide; Edit: D&A team only | R16: Minor: Approver only. Major: Sponsor + Approver. CR via Azure DevOps. | S16: Confidential
B17: 12 | C17: HCM — Payroll Summary | D17: HCM | E17: Live | F17: P1 | G17: Yasir | H17: Ahmad | I17: Oracle Fusion (HCM) | J17: Monthly | K17: Payroll cut-off + 1 day | O17: CFO + HR / People | Q17: View: Department-wide; Edit: D&A team only | R17: Minor: Approver only. Major: Sponsor + Approver. CR via Azure DevOps. | S17: Restricted | T17: Restricted to senior leadership
B18: 13 | C18: Procurement — PO Status & Spend | D18: Procurement | E18: Live | F18: P2 | G18: Yasir | H18: Ahmad | I18: Oracle Fusion (Procurement) | J18: Daily | K18: Daily by 7 AM AST | O18: Procurement Dept | Q18: View: Department-wide; Edit: D&A team only | R18: Minor: Approver only. Major: Sponsor + Approver. CR via Azure DevOps. | S18: Internal | T18: Legacy dashboard — superseded by new Spend Analytics
B19: 14 | C19: IT — System Availability | D19: IT SM | E19: Live | F19: P2 | G19: Yasir | H19: Ahmad | I19: Service Desk Tool | J19: Daily | K19: Daily by 7 AM AST | O19: IT Operations | Q19: View: Department-wide; Edit: D&A team only | R19: Minor: Approver only. Major: Sponsor + Approver. CR via Azure DevOps. | S19: Internal
B20: 15 | C20: Compliance — Regulatory Reporting | D20: Compliance | E20: Live | F20: P1 | G20: Yasir | H20: Ahmad | I20: Mixed (Fusion + Manual) | J20: Monthly | K20: 1st of month by EOD | O20: CSSO + Compliance | Q20: View: Department-wide; Edit: D&A team only | R20: Minor: Approver only. Major: Sponsor + Approver. CR via Azure DevOps. | S20: Restricted | T20: Used for NCA / regulatory submissions
B21: 16 | C21: Executive — KPI Scorecard | D21: Strategy | E21: Live | F21: P1 | G21: Yasir | H21: Ahmad | I21: Mixed (Fusion + Manual) | J21: Weekly | K21: Mondays by 9 AM AST | O21: C-level + Strategy Dept | Q21: View: Department-wide; Edit: D&A team only | R21: Minor: Approver only. Major: Sponsor + Approver. CR via Azure DevOps. | S21: Confidential | T21: Reviewed in weekly leadership meeting
B22: 17 | C22: Procurement — Spend Analytics | D22: Procurement | E22: In Build | F22: P1 | G22: Yasir | H22: Ahmad | I22: Oracle Fusion (Procurement) | J22: Daily | K22: Daily by 7 AM AST | O22: Procurement Dept + CFO | Q22: View: Department-wide; Edit: D&A team only | R22: Minor: Approver only. Major: Sponsor + Approver. CR via Azure DevOps. | S22: Confidential
B23: 18 | C23: Procurement — Supplier Performance | D23: Procurement | E23: In Build | F23: P2 | G23: Yasir | H23: Ahmad | I23: Oracle Fusion (Procurement) | J23: Weekly | K23: Mondays by 9 AM AST | O23: Procurement Dept | Q23: View: Department-wide; Edit: D&A team only | R23: Minor: Approver only. Major: Sponsor + Approver. CR via Azure DevOps. | S23: Internal
B24: 19 | C24: Procurement — PR/PO Cycle Time | D24: Procurement | E24: In Build | F24: P2 | G24: Yasir | H24: Ahmad | I24: Oracle Fusion (Procurement) | J24: Daily | K24: Daily by 7 AM AST | O24: Procurement Dept + Operations | Q24: View: Department-wide; Edit: D&A team only | R24: Minor: Approver only. Major: Sponsor + Approver. CR via Azure DevOps. | S24: Internal
B25: 20 | C25: Procurement — Contract Compliance | D25: Procurement | E25: In Build | F25: P2 | G25: Yasir | H25: Ahmad | I25: Oracle Fusion (Procurement) | J25: Weekly | K25: Mondays by 9 AM AST | O25: Procurement + Legal | Q25: View: Department-wide; Edit: D&A team only | R25: Minor: Approver only. Major: Sponsor + Approver. CR via Azure DevOps. | S25: Confidential
B26: 21 | C26: Strategy — KPI Scorecard | D26: Strategy | E26: In Scoping | F26: P1 | G26: Yasir | H26: Ahmad | I26: Mixed (Fusion + Manual) | J26: Monthly | K26: 1st of month by EOD | O26: Strategy Dept + C-level | Q26: View: Department-wide; Edit: D&A team only | R26: Minor: Approver only. Major: Sponsor + Approver. CR via Azure DevOps. | S26: Confidential
B27: 22 | C27: Strategy — Initiatives Tracker | D27: Strategy | E27: In Scoping | F27: P2 | G27: Yasir | H27: Ahmad | I27: Azure DevOps | J27: Weekly | K27: Mondays by 9 AM AST | O27: Strategy Dept | Q27: View: Department-wide; Edit: D&A team only | R27: Minor: Approver only. Major: Sponsor + Approver. CR via Azure DevOps. | S27: Internal
B28: 23 | C28: Strategy — Performance vs Plan | D28: Strategy | E28: In Scoping | F28: P2 | G28: Yasir | H28: Ahmad | I28: Mixed (Fusion + Manual) | J28: Monthly | K28: 5th of month by EOD | O28: Strategy Dept | Q28: View: Department-wide; Edit: D&A team only | R28: Minor: Approver only. Major: Sponsor + Approver. CR via Azure DevOps. | S28: Confidential
B29: 24 | C29: Strategy — TBD #4 | D29: Strategy | E29: In Scoping | F29: P3 | G29: Yasir | H29: Ahmad | I29: TBD | J29: Monthly | K29: TBD | O29: Strategy Dept | Q29: View: Department-wide; Edit: D&A team only | R29: Minor: Approver only. Major: Sponsor + Approver. CR via Azure DevOps. | S29: Internal
B30: 25 | C30: IT Tickets — SLA & Volume | D30: IT SM | E30: In Build | F30: P2 | G30: Yasir | H30: Ahmad | I30: Service Desk Tool | J30: Daily | K30: Daily by 7 AM AST | O30: IT Operations | Q30: View: Department-wide; Edit: D&A team only | R30: Minor: Approver only. Major: Sponsor + Approver. CR via Azure DevOps. | S30: Internal
B31: 26 | C31: IT Tickets — Backlog & Aging | D31: IT SM | E31: In Build | F31: P2 | G31: Yasir | H31: Ahmad | I31: Service Desk Tool | J31: Daily | K31: Daily by 7 AM AST | O31: IT Operations | Q31: View: Department-wide; Edit: D&A team only | R31: Minor: Approver only. Major: Sponsor + Approver. CR via Azure DevOps. | S31: Internal
B32: 27 | C32: HCM — Headcount & Movements | D32: HCM | E32: In Build | F32: P2 | G32: Yasir | H32: Ahmad | I32: Oracle Fusion (HCM) | J32: Weekly | K32: Mondays by 9 AM AST | O32: HR / People + Department Heads | Q32: View: Department-wide; Edit: D&A team only | R32: Minor: Approver only. Major: Sponsor + Approver. CR via Azure DevOps. | S32: Confidential
B33: 28 | C33: HCM — Attrition & Time-to-Hire | D33: HCM | E33: In Build | F33: P2 | G33: Yasir | H33: Ahmad | I33: Oracle Fusion (HCM) | J33: Monthly | K33: 1st of month by EOD | O33: HR / People | Q33: View: Department-wide; Edit: D&A team only | R33: Minor: Approver only. Major: Sponsor + Approver. CR via Azure DevOps. | S33: Confidential
... B36: 31 | C36: TBD C | D36: TBD | E36: Not Started | F36: P3 | G36: Yasir | H36: Ahmad | I36: TBD | J36: TBD | K36: TBD | O36: TBD | Q36: View: Department-wide; Edit: D&A team only | R36: Minor: Approver only. Major: Sponsor + Approver. CR via Azure DevOps. | S36: Internal

Sheet SLA Tiers
B2: SLA TIERS — KPI × Tier Target Matrix
B3: Single source of truth for tier-driven SLA targets. Ops SLA Tracker pulls targets from here based on each dashboard's tier (set in Dashboard Portfolio). Adjust values per organizational requirements.
B4: KPI | C4: P1 | D4: P2 | E4: P3 | F4: Direction | G4: Unit | H4: Notes
B5: Pipeline availability | C5: 0.999 | D5: 0.995 | E5: 0.99 | F5: H | G5: % | H5: Calendar month, excludes planned maintenance
B6: Data freshness % met | C6: 0.99 | D6: 0.95 | E6: 0.9 | F6: H | G6: % | H6: Window varies per dashboard; set in Portfolio.Refresh Window
B7: Pipeline failures per month | C7: 0 | D7: 2 | E7: 5 | F7: L | G7: Count | H7: Excludes retries that succeed within 30 minutes
B8: Incident MTTR | C8: 2 | D8: 4 | E8: 8 | F8: L | G8: Hours | H8: From incident detection to resolution
B9: Data quality pass rate | C9: 0.99 | D9: 0.98 | E9: 0.95 | F9: H | G9: % | H9: Across all DQ test cases
B10: Dashboard availability | C10: 0.999 | D10: 0.995 | E10: 0.99 | F10: H | G10: % | H10: Power BI service uptime
B11: Avg report load time | C11: 3 | D11: 5 | E11: 8 | F11: L | G11: Seconds | H11: Top dashboards in tier
B12: P1 defect resolution time | C12: 4 | D12: 8 | E12: 24 | F12: L | G12: Hours | H12: From ticket open to fix deployed
B13: Active user adoption | C13: 0.8 | D13: 0.7 | E13: 0.5 | F13: H | G13: % | H13: Monthly active vs target audience size
B14: User CSAT | C14: 4.3 | D14: 4 | E14: 3.8 | F14: H | G14: Score 1-5 | H14: Quarterly survey average
B17: TIER DEFINITIONS
B18: P1 — Critical | C18: Dashboards used by C-level / regulatory / financial close. Outage triggers immediate escalation.
B19: P2 — Important | C19: Dashboards used by department heads or for operational decisions on a weekly basis. Outage notified within 1 hour.
B20: P3 — Standard | C20: Reference / informational dashboards used periodically. Outage handled within standard SLA, no on-call escalation.

Sheet Ops SLA Tracker
B2: OPS SLA TRACKER — Per-Dashboard Monthly SLA Performance
B3: Targets pull from SLA Tiers based on each dashboard's Tier (set in Dashboard Portfolio). Only Actuals are inputs. RAG auto-calculates. Filter Status = Live to focus on production dashboards.
B4: Reporting Period: | C4: MMM-YYYY
B5: ID | C5: Dashboard Name | D5: Status | E5: Tier | F5: Pipeline Avail. (%) | I5: Data Freshness (%) | L5: Pipeline Failures (Cnt) | O5: MTTR (Hrs) | R5: DQ Pass Rate (%) | U5: Dashboard Avail. (%) | X5: Load Time (Sec) | AA5: P1 Defect Resolution (Hrs) | AD5: Adoption (%) | AG5: CSAT (Scr)
F6: Target | G6: Actual | H6: RAG | I6: Target | J6: Actual | K6: RAG | L6: Target | M6: Actual | N6: RAG | O6: Target | P6: Actual | Q6: RAG | R6: Target | S6: Actual | T6: RAG | U6: Target | V6: Actual | W6: RAG | X6: Target | Y6: Actual | Z6: RAG | AA6: Target | AB6: Actual | AC6: RAG | AD6: Target | AE6: Actual | AF6: RAG | AG6: Target | AH6: Actual | AI6: RAG
B7: =IF('Dashboard Portfolio'!B6="","",'Dashboard Portfolio'!B6) -> 1 | C7: =IF('Dashboard Portfolio'!C6="","",'Dashboard Portfolio'!C6) -> Finance — Daily Cash Position | D7: =IF('Dashboard Portfolio'!E6="","",'Dashboard Portfolio'!E6) -> Live | E7: =IF('Dashboard Portfolio'!F6="","",'Dashboard Portfolio'!F6) -> P1 | F7: =IF($D7<>"Live","",IFERROR(HLOOKUP($E7,'SLA Tiers'!$C$4:$E$14,2,FALSE()),"")) -> 0.999 | H7: =IF(OR(G7="",F7=""),"",IF(G7>=F7,"Green",IF(G7>=F7*0.9,"Amber","Red"))) | I7: =IF($D7<>"Live","",IFERROR(HLOOKUP($E7,'SLA Tiers'!$C$4:$E$14,3,FALSE()),"")) -> 0.99 | K7: =IF(OR(J7="",I7=""),"",IF(J7>=I7,"Green",IF(J7>=I7*0.9,"Amber","Red"))) | L7: =IF($D7<>"Live","",IFERROR(HLOOKUP($E7,'SLA Tiers'!$C$4:$E$14,4,FALSE()),"")) -> 0 | N7: =IF(OR(M7="",L7=""),"",IF(M7<=L7,"Green",IF(M7<=L7*1.1,"Amber","Red"))) | O7: =IF($D7<>"Live","",IFERROR(HLOOKUP($E7,'SLA Tiers'!$C$4:$E$14,5,FALSE()),"")) -> 2 | Q7: =IF(OR(P7="",O7=""),"",IF(P7<=O7,"Green",IF(P7<=O7*1.1,"Amber","Red"))) | R7: =IF($D7<>"Live","",IFERROR(HLOOKUP($E7,'SLA Tiers'!$C$4:$E$14,6,FALSE()),"")) -> 0.99 | T7: =IF(OR(S7="",R7=""),"",IF(S7>=R7,"Green",IF(S7>=R7*0.9,"Amber","Red"))) | U7: =IF($D7<>"Live","",IFERROR(HLOOKUP($E7,'SLA Tiers'!$C$4:$E$14,7,FALSE()),"")) -> 0.999 | W7: =IF(OR(V7="",U7=""),"",IF(V7>=U7,"Green",IF(V7>=U7*0.9,"Amber","Red"))) | X7: =IF($D7<>"Live","",IFERROR(HLOOKUP($E7,'SLA Tiers'!$C$4:$E$14,8,FALSE()),"")) -> 3 | Z7: =IF(OR(Y7="",X7=""),"",IF(Y7<=X7,"Green",IF(Y7<=X7*1.1,"Amber","Red"))) | AA7: =IF($D7<>"Live","",IFERROR(HLOOKUP($E7,'SLA Tiers'!$C$4:$E$14,9,FALSE()),"")) -> 4 | AC7: =IF(OR(AB7="",AA7=""),"",IF(AB7<=AA7,"Green",IF(AB7<=AA7*1.1,"Amber","Red"))) | AD7: =IF($D7<>"Live","",IFERROR(HLOOKUP($E7,'SLA Tiers'!$C$4:$E$14,10,FALSE()),"")) -> 0.8 | AF7: =IF(OR(AE7="",AD7=""),"",IF(AE7>=AD7,"Green",IF(AE7>=AD7*0.9,"Amber","Red"))) | AG7: =IF($D7<>"Live","",IFERROR(HLOOKUP($E7,'SLA Tiers'!$C$4:$E$14,11,FALSE()),"")) -> 4.3 | AI7: =IF(OR(AH7="",AG7=""),"",IF(AH7>=AG7,"Green",IF(AH7>=AG7*0.9,"Amber","Red")))
B8: =IF('Dashboard Portfolio'!B7="","",'Dashboard Portfolio'!B7) -> 2 | C8: =IF('Dashboard Portfolio'!C7="","",'Dashboard Portfolio'!C7) -> Finance — AR Aging & Collections | D8: =IF('Dashboard Portfolio'!E7="","",'Dashboard Portfolio'!E7) -> Live | E8: =IF('Dashboard Portfolio'!F7="","",'Dashboard Portfolio'!F7) -> P2 | F8: =IF($D8<>"Live","",IFERROR(HLOOKUP($E8,'SLA Tiers'!$C$4:$E$14,2,FALSE()),"")) -> 0.995 | H8: =IF(OR(G8="",F8=""),"",IF(G8>=F8,"Green",IF(G8>=F8*0.9,"Amber","Red"))) | I8: =IF($D8<>"Live","",IFERROR(HLOOKUP($E8,'SLA Tiers'!$C$4:$E$14,3,FALSE()),"")) -> 0.95 | K8: =IF(OR(J8="",I8=""),"",IF(J8>=I8,"Green",IF(J8>=I8*0.9,"Amber","Red"))) | L8: =IF($D8<>"Live","",IFERROR(HLOOKUP($E8,'SLA Tiers'!$C$4:$E$14,4,FALSE()),"")) -> 2 | N8: =IF(OR(M8="",L8=""),"",IF(M8<=L8,"Green",IF(M8<=L8*1.1,"Amber","Red"))) | O8: =IF($D8<>"Live","",IFERROR(HLOOKUP($E8,'SLA Tiers'!$C$4:$E$14,5,FALSE()),"")) -> 4 | Q8: =IF(OR(P8="",O8=""),"",IF(P8<=O8,"Green",IF(P8<=O8*1.1,"Amber","Red"))) | R8: =IF($D8<>"Live","",IFERROR(HLOOKUP($E8,'SLA Tiers'!$C$4:$E$14,6,FALSE()),"")) -> 0.98 | T8: =IF(OR(S8="",R8=""),"",IF(S8>=R8,"Green",IF(S8>=R8*0.9,"Amber","Red"))) | U8: =IF($D8<>"Live","",IFERROR(HLOOKUP($E8,'SLA Tiers'!$C$4:$E$14,7,FALSE()),"")) -> 0.995 | W8: =IF(OR(V8="",U8=""),"",IF(V8>=U8,"Green",IF(V8>=U8*0.9,"Amber","Red"))) | X8: =IF($D8<>"Live","",IFERROR(HLOOKUP($E8,'SLA Tiers'!$C$4:$E$14,8,FALSE()),"")) -> 5 | Z8: =IF(OR(Y8="",X8=""),"",IF(Y8<=X8,"Green",IF(Y8<=X8*1.1,"Amber","Red"))) | AA8: =IF($D8<>"Live","",IFERROR(HLOOKUP($E8,'SLA Tiers'!$C$4:$E$14,9,FALSE()),"")) -> 8 | AC8: =IF(OR(AB8="",AA8=""),"",IF(AB8<=AA8,"Green",IF(AB8<=AA8*1.1,"Amber","Red"))) | AD8: =IF($D8<>"Live","",IFERROR(HLOOKUP($E8,'SLA Tiers'!$C$4:$E$14,10,FALSE()),"")) -> 0.7 | AF8: =IF(OR(AE8="",AD8=""),"",IF(AE8>=AD8,"Green",IF(AE8>=AD8*0.9,"Amber","Red"))) | AG8: =IF($D8<>"Live","",IFERROR(HLOOKUP($E8,'SLA Tiers'!$C$4:$E$14,11,FALSE()),"")) -> 4 | AI8: =IF(OR(AH8="",AG8=""),"",IF(AH8>=AG8,"Green",IF(AH8>=AG8*0.9,"Amber","Red")))
B9: =IF('Dashboard Portfolio'!B8="","",'Dashboard Portfolio'!B8) -> 3 | C9: =IF('Dashboard Portfolio'!C8="","",'Dashboard Portfolio'!C8) -> Finance — AP Status & Payment Run | D9: =IF('Dashboard Portfolio'!E8="","",'Dashboard Portfolio'!E8) -> Live | E9: =IF('Dashboard Portfolio'!F8="","",'Dashboard Portfolio'!F8) -> P2 | F9: =IF($D9<>"Live","",IFERROR(HLOOKUP($E9,'SLA Tiers'!$C$4:$E$14,2,FALSE()),"")) -> 0.995 | H9: =IF(OR(G9="",F9=""),"",IF(G9>=F9,"Green",IF(G9>=F9*0.9,"Amber","Red"))) | I9: =IF($D9<>"Live","",IFERROR(HLOOKUP($E9,'SLA Tiers'!$C$4:$E$14,3,FALSE()),"")) -> 0.95 | K9: =IF(OR(J9="",I9=""),"",IF(J9>=I9,"Green",IF(J9>=I9*0.9,"Amber","Red"))) | L9: =IF($D9<>"Live","",IFERROR(HLOOKUP($E9,'SLA Tiers'!$C$4:$E$14,4,FALSE()),"")) -> 2 | N9: =IF(OR(M9="",L9=""),"",IF(M9<=L9,"Green",IF(M9<=L9*1.1,"Amber","Red"))) | O9: =IF($D9<>"Live","",IFERROR(HLOOKUP($E9,'SLA Tiers'!$C$4:$E$14,5,FALSE()),"")) -> 4 | Q9: =IF(OR(P9="",O9=""),"",IF(P9<=O9,"Green",IF(P9<=O9*1.1,"Amber","Red"))) | R9: =IF($D9<>"Live","",IFERROR(HLOOKUP($E9,'SLA Tiers'!$C$4:$E$14,6,FALSE()),"")) -> 0.98 | T9: =IF(OR(S9="",R9=""),"",IF(S9>=R9,"Green",IF(S9>=R9*0.9,"Amber","Red"))) | U9: =IF($D9<>"Live","",IFERROR(HLOOKUP($E9,'SLA Tiers'!$C$4:$E$14,7,FALSE()),"")) -> 0.995 | W9: =IF(OR(V9="",U9=""),"",IF(V9>=U9,"Green",IF(V9>=U9*0.9,"Amber","Red"))) | X9: =IF($D9<>"Live","",IFERROR(HLOOKUP($E9,'SLA Tiers'!$C$4:$E$14,8,FALSE()),"")) -> 5 | Z9: =IF(OR(Y9="",X9=""),"",IF(Y9<=X9,"Green",IF(Y9<=X9*1.1,"Amber","Red"))) | AA9: =IF($D9<>"Live","",IFERROR(HLOOKUP($E9,'SLA Tiers'!$C$4:$E$14,9,FALSE()),"")) -> 8 | AC9: =IF(OR(AB9="",AA9=""),"",IF(AB9<=AA9,"Green",IF(AB9<=AA9*1.1,"Amber","Red"))) | AD9: =IF($D9<>"Live","",IFERROR(HLOOKUP($E9,'SLA Tiers'!$C$4:$E$14,10,FALSE()),"")) -> 0.7 | AF9: =IF(OR(AE9="",AD9=""),"",IF(AE9>=AD9,"Green",IF(AE9>=AD9*0.9,"Amber","Red"))) | AG9: =IF($D9<>"Live","",IFERROR(HLOOKUP($E9,'SLA Tiers'!$C$4:$E$14,11,FALSE()),"")) -> 4 | AI9: =IF(OR(AH9="",AG9=""),"",IF(AH9>=AG9,"Green",IF(AH9>=AG9*0.9,"Amber","Red")))
B10: =IF('Dashboard Portfolio'!B9="","",'Dashboard Portfolio'!B9) -> 4 | C10: =IF('Dashboard Portfolio'!C9="","",'Dashboard Portfolio'!C9) -> Finance — Monthly P&L | D10: =IF('Dashboard Portfolio'!E9="","",'Dashboard Portfolio'!E9) -> Live | E10: =IF('Dashboard Portfolio'!F9="","",'Dashboard Portfolio'!F9) -> P1 | F10: =IF($D10<>"Live","",IFERROR(HLOOKUP($E10,'SLA Tiers'!$C$4:$E$14,2,FALSE()),"")) -> 0.999 | H10: =IF(OR(G10="",F10=""),"",IF(G10>=F10,"Green",IF(G10>=F10*0.9,"Amber","Red"))) | I10: =IF($D10<>"Live","",IFERROR(HLOOKUP($E10,'SLA Tiers'!$C$4:$E$14,3,FALSE()),"")) -> 0.99 | K10: =IF(OR(J10="",I10=""),"",IF(J10>=I10,"Green",IF(J10>=I10*0.9,"Amber","Red"))) | L10: =IF($D10<>"Live","",IFERROR(HLOOKUP($E10,'SLA Tiers'!$C$4:$E$14,4,FALSE()),"")) -> 0 | N10: =IF(OR(M10="",L10=""),"",IF(M10<=L10,"Green",IF(M10<=L10*1.1,"Amber","Red"))) | O10: =IF($D10<>"Live","",IFERROR(HLOOKUP($E10,'SLA Tiers'!$C$4:$E$14,5,FALSE()),"")) -> 2 | Q10: =IF(OR(P10="",O10=""),"",IF(P10<=O10,"Green",IF(P10<=O10*1.1,"Amber","Red"))) | R10: =IF($D10<>"Live","",IFERROR(HLOOKUP($E10,'SLA Tiers'!$C$4:$E$14,6,FALSE()),"")) -> 0.99 | T10: =IF(OR(S10="",R10=""),"",IF(S10>=R10,"Green",IF(S10>=R10*0.9,"Amber","Red"))) | U10: =IF($D10<>"Live","",IFERROR(HLOOKUP($E10,'SLA Tiers'!$C$4:$E$14,7,FALSE()),"")) -> 0.999 | W10: =IF(OR(V10="",U10=""),"",IF(V10>=U10,"Green",IF(V10>=U10*0.9,"Amber","Red"))) | X10: =IF($D10<>"Live","",IFERROR(HLOOKUP($E10,'SLA Tiers'!$C$4:$E$14,8,FALSE()),"")) -> 3 | Z10: =IF(OR(Y10="",X10=""),"",IF(Y10<=X10,"Green",IF(Y10<=X10*1.1,"Amber","Red"))) | AA10: =IF($D10<>"Live","",IFERROR(HLOOKUP($E10,'SLA Tiers'!$C$4:$E$14,9,FALSE()),"")) -> 4 | AC10: =IF(OR(AB10="",AA10=""),"",IF(AB10<=AA10,"Green",IF(AB10<=AA10*1.1,"Amber","Red"))) | AD10: =IF($D10<>"Live","",IFERROR(HLOOKUP($E10,'SLA Tiers'!$C$4:$E$14,10,FALSE()),"")) -> 0.8 | AF10: =IF(OR(AE10="",AD10=""),"",IF(AE10>=AD10,"Green",IF(AE10>=AD10*0.9,"Amber","Red"))) | AG10: =IF($D10<>"Live","",IFERROR(HLOOKUP($E10,'SLA Tiers'!$C$4:$E$14,11,FALSE()),"")) -> 4.3 | AI10: =IF(OR(AH10="",AG10=""),"",IF(AH10>=AG10,"Green",IF(AH10>=AG10*0.9,"Amber","Red")))
B11: =IF('Dashboard Portfolio'!B10="","",'Dashboard Portfolio'!B10) -> 5 | C11: =IF('Dashboard Portfolio'!C10="","",'Dashboard Portfolio'!C10) -> Finance — Budget vs Actual | D11: =IF('Dashboard Portfolio'!E10="","",'Dashboard Portfolio'!E10) -> Live | E11: =IF('Dashboard Portfolio'!F10="","",'Dashboard Portfolio'!F10) -> P2 | F11: =IF($D11<>"Live","",IFERROR(HLOOKUP($E11,'SLA Tiers'!$C$4:$E$14,2,FALSE()),"")) -> 0.995 | H11: =IF(OR(G11="",F11=""),"",IF(G11>=F11,"Green",IF(G11>=F11*0.9,"Amber","Red"))) | I11: =IF($D11<>"Live","",IFERROR(HLOOKUP($E11,'SLA Tiers'!$C$4:$E$14,3,FALSE()),"")) -> 0.95 | K11: =IF(OR(J11="",I11=""),"",IF(J11>=I11,"Green",IF(J11>=I11*0.9,"Amber","Red"))) | L11: =IF($D11<>"Live","",IFERROR(HLOOKUP($E11,'SLA Tiers'!$C$4:$E$14,4,FALSE()),"")) -> 2 | N11: =IF(OR(M11="",L11=""),"",IF(M11<=L11,"Green",IF(M11<=L11*1.1,"Amber","Red"))) | O11: =IF($D11<>"Live","",IFERROR(HLOOKUP($E11,'SLA Tiers'!$C$4:$E$14,5,FALSE()),"")) -> 4 | Q11: =IF(OR(P11="",O11=""),"",IF(P11<=O11,"Green",IF(P11<=O11*1.1,"Amber","Red"))) | R11: =IF($D11<>"Live","",IFERROR(HLOOKUP($E11,'SLA Tiers'!$C$4:$E$14,6,FALSE()),"")) -> 0.98 | T11: =IF(OR(S11="",R11=""),"",IF(S11>=R11,"Green",IF(S11>=R11*0.9,"Amber","Red"))) | U11: =IF($D11<>"Live","",IFERROR(HLOOKUP($E11,'SLA Tiers'!$C$4:$E$14,7,FALSE()),"")) -> 0.995 | W11: =IF(OR(V11="",U11=""),"",IF(V11>=U11,"Green",IF(V11>=U11*0.9,"Amber","Red"))) | X11: =IF($D11<>"Live","",IFERROR(HLOOKUP($E11,'SLA Tiers'!$C$4:$E$14,8,FALSE()),"")) -> 5 | Z11: =IF(OR(Y11="",X11=""),"",IF(Y11<=X11,"Green",IF(Y11<=X11*1.1,"Amber","Red"))) | AA11: =IF($D11<>"Live","",IFERROR(HLOOKUP($E11,'SLA Tiers'!$C$4:$E$14,9,FALSE()),"")) -> 8 | AC11: =IF(OR(AB11="",AA11=""),"",IF(AB11<=AA11,"Green",IF(AB11<=AA11*1.1,"Amber","Red"))) | AD11: =IF($D11<>"Live","",IFERROR(HLOOKUP($E11,'SLA Tiers'!$C$4:$E$14,10,FALSE()),"")) -> 0.7 | AF11: =IF(OR(AE11="",AD11=""),"",IF(AE11>=AD11,"Green",IF(AE11>=AD11*0.9,"Amber","Red"))) | AG11: =IF($D11<>"Live","",IFERROR(HLOOKUP($E11,'SLA Tiers'!$C$4:$E$14,11,FALSE()),"")) -> 4 | AI11: =IF(OR(AH11="",AG11=""),"",IF(AH11>=AG11,"Green",IF(AH11>=AG11*0.9,"Amber","Red")))
B12: =IF('Dashboard Portfolio'!B11="","",'Dashboard Portfolio'!B11) -> 6 | C12: =IF('Dashboard Portfolio'!C11="","",'Dashboard Portfolio'!C11) -> Operations — Property Occupancy | D12: =IF('Dashboard Portfolio'!E11="","",'Dashboard Portfolio'!E11) -> Live | E12: =IF('Dashboard Portfolio'!F11="","",'Dashboard Portfolio'!F11) -> P1 | F12: =IF($D12<>"Live","",IFERROR(HLOOKUP($E12,'SLA Tiers'!$C$4:$E$14,2,FALSE()),"")) -> 0.999 | H12: =IF(OR(G12="",F12=""),"",IF(G12>=F12,"Green",IF(G12>=F12*0.9,"Amber","Red"))) | I12: =IF($D12<>"Live","",IFERROR(HLOOKUP($E12,'SLA Tiers'!$C$4:$E$14,3,FALSE()),"")) -> 0.99 | K12: =IF(OR(J12="",I12=""),"",IF(J12>=I12,"Green",IF(J12>=I12*0.9,"Amber","Red"))) | L12: =IF($D12<>"Live","",IFERROR(HLOOKUP($E12,'SLA Tiers'!$C$4:$E$14,4,FALSE()),"")) -> 0 | N12: =IF(OR(M12="",L12=""),"",IF(M12<=L12,"Green",IF(M12<=L12*1.1,"Amber","Red"))) | O12: =IF($D12<>"Live","",IFERROR(HLOOKUP($E12,'SLA Tiers'!$C$4:$E$14,5,FALSE()),"")) -> 2 | Q12: =IF(OR(P12="",O12=""),"",IF(P12<=O12,"Green",IF(P12<=O12*1.1,"Amber","Red"))) | R12: =IF($D12<>"Live","",IFERROR(HLOOKUP($E12,'SLA Tiers'!$C$4:$E$14,6,FALSE()),"")) -> 0.99 | T12: =IF(OR(S12="",R12=""),"",IF(S12>=R12,"Green",IF(S12>=R12*0.9,"Amber","Red"))) | U12: =IF($D12<>"Live","",IFERROR(HLOOKUP($E12,'SLA Tiers'!$C$4:$E$14,7,FALSE()),"")) -> 0.999 | W12: =IF(OR(V12="",U12=""),"",IF(V12>=U12,"Green",IF(V12>=U12*0.9,"Amber","Red"))) | X12: =IF($D12<>"Live","",IFERROR(HLOOKUP($E12,'SLA Tiers'!$C$4:$E$14,8,FALSE()),"")) -> 3 | Z12: =IF(OR(Y12="",X12=""),"",IF(Y12<=X12,"Green",IF(Y12<=X12*1.1,"Amber","Red"))) | AA12: =IF($D12<>"Live","",IFERROR(HLOOKUP($E12,'SLA Tiers'!$C$4:$E$14,9,FALSE()),"")) -> 4 | AC12: =IF(OR(AB12="",AA12=""),"",IF(AB12<=AA12,"Green",IF(AB12<=AA12*1.1,"Amber","Red"))) | AD12: =IF($D12<>"Live","",IFERROR(HLOOKUP($E12,'SLA Tiers'!$C$4:$E$14,10,FALSE()),"")) -> 0.8 | AF12: =IF(OR(AE12="",AD12=""),"",IF(AE12>=AD12,"Green",IF(AE12>=AD12*0.9,"Amber","Red"))) | AG12: =IF($D12<>"Live","",IFERROR(HLOOKUP($E12,'SLA Tiers'!$C$4:$E$14,11,FALSE()),"")) -> 4.3 | AI12: =IF(OR(AH12="",AG12=""),"",IF(AH12>=AG12,"Green",IF(AH12>=AG12*0.9,"Amber","Red")))
B13: =IF('Dashboard Portfolio'!B12="","",'Dashboard Portfolio'!B12) -> 7 | C13: =IF('Dashboard Portfolio'!C12="","",'Dashboard Portfolio'!C12) -> Operations — Lease Renewals & Expiries | D13: =IF('Dashboard Portfolio'!E12="","",'Dashboard Portfolio'!E12) -> Live | E13: =IF('Dashboard Portfolio'!F12="","",'Dashboard Portfolio'!F12) -> P2 | F13: =IF($D13<>"Live","",IFERROR(HLOOKUP($E13,'SLA Tiers'!$C$4:$E$14,2,FALSE()),"")) -> 0.995 | H13: =IF(OR(G13="",F13=""),"",IF(G13>=F13,"Green",IF(G13>=F13*0.9,"Amber","Red"))) | I13: =IF($D13<>"Live","",IFERROR(HLOOKUP($E13,'SLA Tiers'!$C$4:$E$14,3,FALSE()),"")) -> 0.95 | K13: =IF(OR(J13="",I13=""),"",IF(J13>=I13,"Green",IF(J13>=I13*0.9,"Amber","Red"))) | L13: =IF($D13<>"Live","",IFERROR(HLOOKUP($E13,'SLA Tiers'!$C$4:$E$14,4,FALSE()),"")) -> 2 | N13: =IF(OR(M13="",L13=""),"",IF(M13<=L13,"Green",IF(M13<=L13*1.1,"Amber","Red"))) | O13: =IF($D13<>"Live","",IFERROR(HLOOKUP($E13,'SLA Tiers'!$C$4:$E$14,5,FALSE()),"")) -> 4 | Q13: =IF(OR(P13="",O13=""),"",IF(P13<=O13,"Green",IF(P13<=O13*1.1,"Amber","Red"))) | R13: =IF($D13<>"Live","",IFERROR(HLOOKUP($E13,'SLA Tiers'!$C$4:$E$14,6,FALSE()),"")) -> 0.98 | T13: =IF(OR(S13="",R13=""),"",IF(S13>=R13,"Green",IF(S13>=R13*0.9,"Amber","Red"))) | U13: =IF($D13<>"Live","",IFERROR(HLOOKUP($E13,'SLA Tiers'!$C$4:$E$14,7,FALSE()),"")) -> 0.995 | W13: =IF(OR(V13="",U13=""),"",IF(V13>=U13,"Green",IF(V13>=U13*0.9,"Amber","Red"))) | X13: =IF($D13<>"Live","",IFERROR(HLOOKUP($E13,'SLA Tiers'!$C$4:$E$14,8,FALSE()),"")) -> 5 | Z13: =IF(OR(Y13="",X13=""),"",IF(Y13<=X13,"Green",IF(Y13<=X13*1.1,"Amber","Red"))) | AA13: =IF($D13<>"Live","",IFERROR(HLOOKUP($E13,'SLA Tiers'!$C$4:$E$14,9,FALSE()),"")) -> 8 | AC13: =IF(OR(AB13="",AA13=""),"",IF(AB13<=AA13,"Green",IF(AB13<=AA13*1.1,"Amber","Red"))) | AD13: =IF($D13<>"Live","",IFERROR(HLOOKUP($E13,'SLA Tiers'!$C$4:$E$14,10,FALSE()),"")) -> 0.7 | AF13: =IF(OR(AE13="",AD13=""),"",IF(AE13>=AD13,"Green",IF(AE13>=AD13*0.9,"Amber","Red"))) | AG13: =IF($D13<>"Live","",IFERROR(HLOOKUP($E13,'SLA Tiers'!$C$4:$E$14,11,FALSE()),"")) -> 4 | AI13: =IF(OR(AH13="",AG13=""),"",IF(AH13>=AG13,"Green",IF(AH13>=AG13*0.9,"Amber","Red")))
B14: =IF('Dashboard Portfolio'!B13="","",'Dashboard Portfolio'!B13) -> 8 | C14: =IF('Dashboard Portfolio'!C13="","",'Dashboard Portfolio'!C13) -> Operations — Revenue by Asset | D14: =IF('Dashboard Portfolio'!E13="","",'Dashboard Portfolio'!E13) -> Live | E14: =IF('Dashboard Portfolio'!F13="","",'Dashboard Portfolio'!F13) -> P1 | F14: =IF($D14<>"Live","",IFERROR(HLOOKUP($E14,'SLA Tiers'!$C$4:$E$14,2,FALSE()),"")) -> 0.999 | H14: =IF(OR(G14="",F14=""),"",IF(G14>=F14,"Green",IF(G14>=F14*0.9,"Amber","Red"))) | I14: =IF($D14<>"Live","",IFERROR(HLOOKUP($E14,'SLA Tiers'!$C$4:$E$14,3,FALSE()),"")) -> 0.99 | K14: =IF(OR(J14="",I14=""),"",IF(J14>=I14,"Green",IF(J14>=I14*0.9,"Amber","Red"))) | L14: =IF($D14<>"Live","",IFERROR(HLOOKUP($E14,'SLA Tiers'!$C$4:$E$14,4,FALSE()),"")) -> 0 | N14: =IF(OR(M14="",L14=""),"",IF(M14<=L14,"Green",IF(M14<=L14*1.1,"Amber","Red"))) | O14: =IF($D14<>"Live","",IFERROR(HLOOKUP($E14,'SLA Tiers'!$C$4:$E$14,5,FALSE()),"")) -> 2 | Q14: =IF(OR(P14="",O14=""),"",IF(P14<=O14,"Green",IF(P14<=O14*1.1,"Amber","Red"))) | R14: =IF($D14<>"Live","",IFERROR(HLOOKUP($E14,'SLA Tiers'!$C$4:$E$14,6,FALSE()),"")) -> 0.99 | T14: =IF(OR(S14="",R14=""),"",IF(S14>=R14,"Green",IF(S14>=R14*0.9,"Amber","Red"))) | U14: =IF($D14<>"Live","",IFERROR(HLOOKUP($E14,'SLA Tiers'!$C$4:$E$14,7,FALSE()),"")) -> 0.999 | W14: =IF(OR(V14="",U14=""),"",IF(V14>=U14,"Green",IF(V14>=U14*0.9,"Amber","Red"))) | X14: =IF($D14<>"Live","",IFERROR(HLOOKUP($E14,'SLA Tiers'!$C$4:$E$14,8,FALSE()),"")) -> 3 | Z14: =IF(OR(Y14="",X14=""),"",IF(Y14<=X14,"Green",IF(Y14<=X14*1.1,"Amber","Red"))) | AA14: =IF($D14<>"Live","",IFERROR(HLOOKUP($E14,'SLA Tiers'!$C$4:$E$14,9,FALSE()),"")) -> 4 | AC14: =IF(OR(AB14="",AA14=""),"",IF(AB14<=AA14,"Green",IF(AB14<=AA14*1.1,"Amber","Red"))) | AD14: =IF($D14<>"Live","",IFERROR(HLOOKUP($E14,'SLA Tiers'!$C$4:$E$14,10,FALSE()),"")) -> 0.8 | AF14: =IF(OR(AE14="",AD14=""),"",IF(AE14>=AD14,"Green",IF(AE14>=AD14*0.9,"Amber","Red"))) | AG14: =IF($D14<>"Live","",IFERROR(HLOOKUP($E14,'SLA Tiers'!$C$4:$E$14,11,FALSE()),"")) -> 4.3 | AI14: =IF(OR(AH14="",AG14=""),"",IF(AH14>=AG14,"Green",IF(AH14>=AG14*0.9,"Amber","Red")))
B15: =IF('Dashboard Portfolio'!B14="","",'Dashboard Portfolio'!B14) -> 9 | C15: =IF('Dashboard Portfolio'!C14="","",'Dashboard Portfolio'!C14) -> Operations — Maintenance Tickets | D15: =IF('Dashboard Portfolio'!E14="","",'Dashboard Portfolio'!E14) -> Live | E15: =IF('Dashboard Portfolio'!F14="","",'Dashboard Portfolio'!F14) -> P2 | F15: =IF($D15<>"Live","",IFERROR(HLOOKUP($E15,'SLA Tiers'!$C$4:$E$14,2,FALSE()),"")) -> 0.995 | H15: =IF(OR(G15="",F15=""),"",IF(G15>=F15,"Green",IF(G15>=F15*0.9,"Amber","Red"))) | I15: =IF($D15<>"Live","",IFERROR(HLOOKUP($E15,'SLA Tiers'!$C$4:$E$14,3,FALSE()),"")) -> 0.95 | K15: =IF(OR(J15="",I15=""),"",IF(J15>=I15,"Green",IF(J15>=I15*0.9,"Amber","Red"))) | L15: =IF($D15<>"Live","",IFERROR(HLOOKUP($E15,'SLA Tiers'!$C$4:$E$14,4,FALSE()),"")) -> 2 | N15: =IF(OR(M15="",L15=""),"",IF(M15<=L15,"Green",IF(M15<=L15*1.1,"Amber","Red"))) | O15: =IF($D15<>"Live","",IFERROR(HLOOKUP($E15,'SLA Tiers'!$C$4:$E$14,5,FALSE()),"")) -> 4 | Q15: =IF(OR(P15="",O15=""),"",IF(P15<=O15,"Green",IF(P15<=O15*1.1,"Amber","Red"))) | R15: =IF($D15<>"Live","",IFERROR(HLOOKUP($E15,'SLA Tiers'!$C$4:$E$14,6,FALSE()),"")) -> 0.98 | T15: =IF(OR(S15="",R15=""),"",IF(S15>=R15,"Green",IF(S15>=R15*0.9,"Amber","Red"))) | U15: =IF($D15<>"Live","",IFERROR(HLOOKUP($E15,'SLA Tiers'!$C$4:$E$14,7,FALSE()),"")) -> 0.995 | W15: =IF(OR(V15="",U15=""),"",IF(V15>=U15,"Green",IF(V15>=U15*0.9,"Amber","Red"))) | X15: =IF($D15<>"Live","",IFERROR(HLOOKUP($E15,'SLA Tiers'!$C$4:$E$14,8,FALSE()),"")) -> 5 | Z15: =IF(OR(Y15="",X15=""),"",IF(Y15<=X15,"Green",IF(Y15<=X15*1.1,"Amber","Red"))) | AA15: =IF($D15<>"Live","",IFERROR(HLOOKUP($E15,'SLA Tiers'!$C$4:$E$14,9,FALSE()),"")) -> 8 | AC15: =IF(OR(AB15="",AA15=""),"",IF(AB15<=AA15,"Green",IF(AB15<=AA15*1.1,"Amber","Red"))) | AD15: =IF($D15<>"Live","",IFERROR(HLOOKUP($E15,'SLA Tiers'!$C$4:$E$14,10,FALSE()),"")) -> 0.7 | AF15: =IF(OR(AE15="",AD15=""),"",IF(AE15>=AD15,"Green",IF(AE15>=AD15*0.9,"Amber","Red"))) | AG15: =IF($D15<>"Live","",IFERROR(HLOOKUP($E15,'SLA Tiers'!$C$4:$E$14,11,FALSE()),"")) -> 4 | AI15: =IF(OR(AH15="",AG15=""),"",IF(AH15>=AG15,"Green",IF(AH15>=AG15*0.9,"Amber","Red")))
B16: =IF('Dashboard Portfolio'!B15="","",'Dashboard Portfolio'!B15) -> 10 | C16: =IF('Dashboard Portfolio'!C15="","",'Dashboard Portfolio'!C15) -> HCM — Headcount & Org | D16: =IF('Dashboard Portfolio'!E15="","",'Dashboard Portfolio'!E15) -> Live | E16: =IF('Dashboard Portfolio'!F15="","",'Dashboard Portfolio'!F15) -> P2 | F16: =IF($D16<>"Live","",IFERROR(HLOOKUP($E16,'SLA Tiers'!$C$4:$E$14,2,FALSE()),"")) -> 0.995 | H16: =IF(OR(G16="",F16=""),"",IF(G16>=F16,"Green",IF(G16>=F16*0.9,"Amber","Red"))) | I16: =IF($D16<>"Live","",IFERROR(HLOOKUP($E16,'SLA Tiers'!$C$4:$E$14,3,FALSE()),"")) -> 0.95 | K16: =IF(OR(J16="",I16=""),"",IF(J16>=I16,"Green",IF(J16>=I16*0.9,"Amber","Red"))) | L16: =IF($D16<>"Live","",IFERROR(HLOOKUP($E16,'SLA Tiers'!$C$4:$E$14,4,FALSE()),"")) -> 2 | N16: =IF(OR(M16="",L16=""),"",IF(M16<=L16,"Green",IF(M16<=L16*1.1,"Amber","Red"))) | O16: =IF($D16<>"Live","",IFERROR(HLOOKUP($E16,'SLA Tiers'!$C$4:$E$14,5,FALSE()),"")) -> 4 | Q16: =IF(OR(P16="",O16=""),"",IF(P16<=O16,"Green",IF(P16<=O16*1.1,"Amber","Red"))) | R16: =IF($D16<>"Live","",IFERROR(HLOOKUP($E16,'SLA Tiers'!$C$4:$E$14,6,FALSE()),"")) -> 0.98 | T16: =IF(OR(S16="",R16=""),"",IF(S16>=R16,"Green",IF(S16>=R16*0.9,"Amber","Red"))) | U16: =IF($D16<>"Live","",IFERROR(HLOOKUP($E16,'SLA Tiers'!$C$4:$E$14,7,FALSE()),"")) -> 0.995 | W16: =IF(OR(V16="",U16=""),"",IF(V16>=U16,"Green",IF(V16>=U16*0.9,"Amber","Red"))) | X16: =IF($D16<>"Live","",IFERROR(HLOOKUP($E16,'SLA Tiers'!$C$4:$E$14,8,FALSE()),"")) -> 5 | Z16: =IF(OR(Y16="",X16=""),"",IF(Y16<=X16,"Green",IF(Y16<=X16*1.1,"Amber","Red"))) | AA16: =IF($D16<>"Live","",IFERROR(HLOOKUP($E16,'SLA Tiers'!$C$4:$E$14,9,FALSE()),"")) -> 8 | AC16: =IF(OR(AB16="",AA16=""),"",IF(AB16<=AA16,"Green",IF(AB16<=AA16*1.1,"Amber","Red"))) | AD16: =IF($D16<>"Live","",IFERROR(HLOOKUP($E16,'SLA Tiers'!$C$4:$E$14,10,FALSE()),"")) -> 0.7 | AF16: =IF(OR(AE16="",AD16=""),"",IF(AE16>=AD16,"Green",IF(AE16>=AD16*0.9,"Amber","Red"))) | AG16: =IF($D16<>"Live","",IFERROR(HLOOKUP($E16,'SLA Tiers'!$C$4:$E$14,11,FALSE()),"")) -> 4 | AI16: =IF(OR(AH16="",AG16=""),"",IF(AH16>=AG16,"Green",IF(AH16>=AG16*0.9,"Amber","Red")))
B17: =IF('Dashboard Portfolio'!B16="","",'Dashboard Portfolio'!B16) -> 11 | C17: =IF('Dashboard Portfolio'!C16="","",'Dashboard Portfolio'!C16) -> HCM — Attendance & Leave | D17: =IF('Dashboard Portfolio'!E16="","",'Dashboard Portfolio'!E16) -> Live | E17: =IF('Dashboard Portfolio'!F16="","",'Dashboard Portfolio'!F16) -> P3 | F17: =IF($D17<>"Live","",IFERROR(HLOOKUP($E17,'SLA Tiers'!$C$4:$E$14,2,FALSE()),"")) -> 0.99 | H17: =IF(OR(G17="",F17=""),"",IF(G17>=F17,"Green",IF(G17>=F17*0.9,"Amber","Red"))) | I17: =IF($D17<>"Live","",IFERROR(HLOOKUP($E17,'SLA Tiers'!$C$4:$E$14,3,FALSE()),"")) -> 0.9 | K17: =IF(OR(J17="",I17=""),"",IF(J17>=I17,"Green",IF(J17>=I17*0.9,"Amber","Red"))) | L17: =IF($D17<>"Live","",IFERROR(HLOOKUP($E17,'SLA Tiers'!$C$4:$E$14,4,FALSE()),"")) -> 5 | N17: =IF(OR(M17="",L17=""),"",IF(M17<=L17,"Green",IF(M17<=L17*1.1,"Amber","Red"))) | O17: =IF($D17<>"Live","",IFERROR(HLOOKUP($E17,'SLA Tiers'!$C$4:$E$14,5,FALSE()),"")) -> 8 | Q17: =IF(OR(P17="",O17=""),"",IF(P17<=O17,"Green",IF(P17<=O17*1.1,"Amber","Red"))) | R17: =IF($D17<>"Live","",IFERROR(HLOOKUP($E17,'SLA Tiers'!$C$4:$E$14,6,FALSE()),"")) -> 0.95 | T17: =IF(OR(S17="",R17=""),"",IF(S17>=R17,"Green",IF(S17>=R17*0.9,"Amber","Red"))) | U17: =IF($D17<>"Live","",IFERROR(HLOOKUP($E17,'SLA Tiers'!$C$4:$E$14,7,FALSE()),"")) -> 0.99 | W17: =IF(OR(V17="",U17=""),"",IF(V17>=U17,"Green",IF(V17>=U17*0.9,"Amber","Red"))) | X17: =IF($D17<>"Live","",IFERROR(HLOOKUP($E17,'SLA Tiers'!$C$4:$E$14,8,FALSE()),"")) -> 8 | Z17: =IF(OR(Y17="",X17=""),"",IF(Y17<=X17,"Green",IF(Y17<=X17*1.1,"Amber","Red"))) | AA17: =IF($D17<>"Live","",IFERROR(HLOOKUP($E17,'SLA Tiers'!$C$4:$E$14,9,FALSE()),"")) -> 24 | AC17: =IF(OR(AB17="",AA17=""),"",IF(AB17<=AA17,"Green",IF(AB17<=AA17*1.1,"Amber","Red"))) | AD17: =IF($D17<>"Live","",IFERROR(HLOOKUP($E17,'SLA Tiers'!$C$4:$E$14,10,FALSE()),"")) -> 0.5 | AF17: =IF(OR(AE17="",AD17=""),"",IF(AE17>=AD17,"Green",IF(AE17>=AD17*0.9,"Amber","Red"))) | AG17: =IF($D17<>"Live","",IFERROR(HLOOKUP($E17,'SLA Tiers'!$C$4:$E$14,11,FALSE()),"")) -> 3.8 | AI17: =IF(OR(AH17="",AG17=""),"",IF(AH17>=AG17,"Green",IF(AH17>=AG17*0.9,"Amber","Red")))
B18: =IF('Dashboard Portfolio'!B17="","",'Dashboard Portfolio'!B17) -> 12 | C18: =IF('Dashboard Portfolio'!C17="","",'Dashboard Portfolio'!C17) -> HCM — Payroll Summary | D18: =IF('Dashboard Portfolio'!E17="","",'Dashboard Portfolio'!E17) -> Live | E18: =IF('Dashboard Portfolio'!F17="","",'Dashboard Portfolio'!F17) -> P1 | F18: =IF($D18<>"Live","",IFERROR(HLOOKUP($E18,'SLA Tiers'!$C$4:$E$14,2,FALSE()),"")) -> 0.999 | H18: =IF(OR(G18="",F18=""),"",IF(G18>=F18,"Green",IF(G18>=F18*0.9,"Amber","Red"))) | I18: =IF($D18<>"Live","",IFERROR(HLOOKUP($E18,'SLA Tiers'!$C$4:$E$14,3,FALSE()),"")) -> 0.99 | K18: =IF(OR(J18="",I18=""),"",IF(J18>=I18,"Green",IF(J18>=I18*0.9,"Amber","Red"))) | L18: =IF($D18<>"Live","",IFERROR(HLOOKUP($E18,'SLA Tiers'!$C$4:$E$14,4,FALSE()),"")) -> 0 | N18: =IF(OR(M18="",L18=""),"",IF(M18<=L18,"Green",IF(M18<=L18*1.1,"Amber","Red"))) | O18: =IF($D18<>"Live","",IFERROR(HLOOKUP($E18,'SLA Tiers'!$C$4:$E$14,5,FALSE()),"")) -> 2 | Q18: =IF(OR(P18="",O18=""),"",IF(P18<=O18,"Green",IF(P18<=O18*1.1,"Amber","Red"))) | R18: =IF($D18<>"Live","",IFERROR(HLOOKUP($E18,'SLA Tiers'!$C$4:$E$14,6,FALSE()),"")) -> 0.99 | T18: =IF(OR(S18="",R18=""),"",IF(S18>=R18,"Green",IF(S18>=R18*0.9,"Amber","Red"))) | U18: =IF($D18<>"Live","",IFERROR(HLOOKUP($E18,'SLA Tiers'!$C$4:$E$14,7,FALSE()),"")) -> 0.999 | W18: =IF(OR(V18="",U18=""),"",IF(V18>=U18,"Green",IF(V18>=U18*0.9,"Amber","Red"))) | X18: =IF($D18<>"Live","",IFERROR(HLOOKUP($E18,'SLA Tiers'!$C$4:$E$14,8,FALSE()),"")) -> 3 | Z18: =IF(OR(Y18="",X18=""),"",IF(Y18<=X18,"Green",IF(Y18<=X18*1.1,"Amber","Red"))) | AA18: =IF($D18<>"Live","",IFERROR(HLOOKUP($E18,'SLA Tiers'!$C$4:$E$14,9,FALSE()),"")) -> 4 | AC18: =IF(OR(AB18="",AA18=""),"",IF(AB18<=AA18,"Green",IF(AB18<=AA18*1.1,"Amber","Red"))) | AD18: =IF($D18<>"Live","",IFERROR(HLOOKUP($E18,'SLA Tiers'!$C$4:$E$14,10,FALSE()),"")) -> 0.8 | AF18: =IF(OR(AE18="",AD18=""),"",IF(AE18>=AD18,"Green",IF(AE18>=AD18*0.9,"Amber","Red"))) | AG18: =IF($D18<>"Live","",IFERROR(HLOOKUP($E18,'SLA Tiers'!$C$4:$E$14,11,FALSE()),"")) -> 4.3 | AI18: =IF(OR(AH18="",AG18=""),"",IF(AH18>=AG18,"Green",IF(AH18>=AG18*0.9,"Amber","Red")))
... B37: =IF('Dashboard Portfolio'!B36="","",'Dashboard Portfolio'!B36) -> 31 | C37: =IF('Dashboard Portfolio'!C36="","",'Dashboard Portfolio'!C36) -> TBD C | D37: =IF('Dashboard Portfolio'!E36="","",'Dashboard Portfolio'!E36) -> Not Started | E37: =IF('Dashboard Portfolio'!F36="","",'Dashboard Portfolio'!F36) -> P3 | F37: =IF($D37<>"Live","",IFERROR(HLOOKUP($E37,'SLA Tiers'!$C$4:$E$14,2,FALSE()),"")) | H37: =IF(OR(G37="",F37=""),"",IF(G37>=F37,"Green",IF(G37>=F37*0.9,"Amber","Red"))) | I37: =IF($D37<>"Live","",IFERROR(HLOOKUP($E37,'SLA Tiers'!$C$4:$E$14,3,FALSE()),"")) | K37: =IF(OR(J37="",I37=""),"",IF(J37>=I37,"Green",IF(J37>=I37*0.9,"Amber","Red"))) | L37: =IF($D37<>"Live","",IFERROR(HLOOKUP($E37,'SLA Tiers'!$C$4:$E$14,4,FALSE()),"")) | N37: =IF(OR(M37="",L37=""),"",IF(M37<=L37,"Green",IF(M37<=L37*1.1,"Amber","Red"))) | O37: =IF($D37<>"Live","",IFERROR(HLOOKUP($E37,'SLA Tiers'!$C$4:$E$14,5,FALSE()),"")) | Q37: =IF(OR(P37="",O37=""),"",IF(P37<=O37,"Green",IF(P37<=O37*1.1,"Amber","Red"))) | R37: =IF($D37<>"Live","",IFERROR(HLOOKUP($E37,'SLA Tiers'!$C$4:$E$14,6,FALSE()),"")) | T37: =IF(OR(S37="",R37=""),"",IF(S37>=R37,"Green",IF(S37>=R37*0.9,"Amber","Red"))) | U37: =IF($D37<>"Live","",IFERROR(HLOOKUP($E37,'SLA Tiers'!$C$4:$E$14,7,FALSE()),"")) | W37: =IF(OR(V37="",U37=""),"",IF(V37>=U37,"Green",IF(V37>=U37*0.9,"Amber","Red"))) | X37: =IF($D37<>"Live","",IFERROR(HLOOKUP($E37,'SLA Tiers'!$C$4:$E$14,8,FALSE()),"")) | Z37: =IF(OR(Y37="",X37=""),"",IF(Y37<=X37,"Green",IF(Y37<=X37*1.1,"Amber","Red"))) | AA37: =IF($D37<>"Live","",IFERROR(HLOOKUP($E37,'SLA Tiers'!$C$4:$E$14,9,FALSE()),"")) | AC37: =IF(OR(AB37="",AA37=""),"",IF(AB37<=AA37,"Green",IF(AB37<=AA37*1.1,"Amber","Red"))) | AD37: =IF($D37<>"Live","",IFERROR(HLOOKUP($E37,'SLA Tiers'!$C$4:$E$14,10,FALSE()),"")) | AF37: =IF(OR(AE37="",AD37=""),"",IF(AE37>=AD37,"Green",IF(AE37>=AD37*0.9,"Amber","Red"))) | AG37: =IF($D37<>"Live","",IFERROR(HLOOKUP($E37,'SLA Tiers'!$C$4:$E$14,11,FALSE()),"")) | AI37: =IF(OR(AH37="",AG37=""),"",IF(AH37>=AG37,"Green",IF(AH37>=AG37*0.9,"Amber","Red")))

Sheet Delivery Tracker
B2: DELIVERY TRACKER — 15 New Dashboards
B3: 7 stages: BRD → Design Approval → Data Model → Pipeline → Visual → UAT → Production. Yellow = inputs; Status, % Complete, and Summary KPIs auto-calculate. Summary feeds Scorecard.
C5: Dashboard | D5: Domain | E5: S1: BRD | G5: S2: Design Approval | I5: S3: Data Model (Fusion) | K5: S4: Pipeline (DE) | M5: S5: Visual (BI) | O5: S6: UAT | Q5: S7: Production | S5: Status | T5: % Complete
E6: Planned | F6: Actual | G6: Planned | H6: Actual | I6: Planned | J6: Actual | K6: Planned | L6: Actual | M6: Planned | N6: Actual | O6: Planned | P6: Actual | Q6: Planned | R6: Actual
B7: 1 | C7: Procurement — Spend Analytics | D7: Procurement | E7: 46037 | F7: 46042 | G7: 46054 | H7: 46058 | I7: 46073 | J7: 46078 | K7: 46096 | L7: 46101 | M7: 46117 | N7: 46122 | O7: 46137 | P7: 46143 | Q7: 46157 | S7: =IF(COUNTA(F7,H7,J7,L7,N7,P7,R7)=0,"Not Started",IF(R7<>"","In Production",IF(P7<>"","UAT Complete",IF(N7<>"","Visual Complete",IF(L7<>"","Pipeline Complete",IF(J7<>"","Data Model Complete",IF(H7<>"","Design Approved",IF(F7<>"","BRD Complete","Not Started")))))))) -> UAT Complete | T7: =COUNTA(F7,H7,J7,L7,N7,P7,R7)/7 -> 0.85714286
B8: 2 | C8: Procurement — Supplier Performance | D8: Procurement | E8: 46052 | F8: 46056 | G8: 46068 | H8: 46073 | I8: 46086 | J8: 46091 | K8: 46106 | L8: 46114 | M8: 46132 | N8: 46147 | O8: 46157 | Q8: 46174 | S8: =IF(COUNTA(F8,H8,J8,L8,N8,P8,R8)=0,"Not Started",IF(R8<>"","In Production",IF(P8<>"","UAT Complete",IF(N8<>"","Visual Complete",IF(L8<>"","Pipeline Complete",IF(J8<>"","Data Model Complete",IF(H8<>"","Design Approved",IF(F8<>"","BRD Complete","Not Started")))))))) -> Visual Complete | T8: =COUNTA(F8,H8,J8,L8,N8,P8,R8)/7 -> 0.71428571
B9: 3 | C9: Procurement — PR/PO Cycle Time | D9: Procurement | E9: 46054 | F9: 46058 | G9: 46073 | H9: 46081 | I9: 46096 | J9: 46101 | K9: 46122 | L9: 46145 | M9: 46142 | O9: 46162 | Q9: 46178 | S9: =IF(COUNTA(F9,H9,J9,L9,N9,P9,R9)=0,"Not Started",IF(R9<>"","In Production",IF(P9<>"","UAT Complete",IF(N9<>"","Visual Complete",IF(L9<>"","Pipeline Complete",IF(J9<>"","Data Model Complete",IF(H9<>"","Design Approved",IF(F9<>"","BRD Complete","Not Started")))))))) -> Pipeline Complete | T9: =COUNTA(F9,H9,J9,L9,N9,P9,R9)/7 -> 0.57142857
B10: 4 | C10: Procurement — Contract Compliance | D10: Procurement | E10: 46068 | F10: 46073 | G10: 46086 | H10: 46093 | I10: 46113 | J10: 46137 | K10: 46137 | M10: 46157 | O10: 46178 | Q10: 46193 | S10: =IF(COUNTA(F10,H10,J10,L10,N10,P10,R10)=0,"Not Started",IF(R10<>"","In Production",IF(P10<>"","UAT Complete",IF(N10<>"","Visual Complete",IF(L10<>"","Pipeline Complete",IF(J10<>"","Data Model Complete",IF(H10<>"","Design Approved",IF(F10<>"","BRD Complete","Not Started")))))))) -> Data Model Complete | T10: =COUNTA(F10,H10,J10,L10,N10,P10,R10)/7 -> 0.42857143
B11: 5 | C11: Strategy — KPI Scorecard | D11: Strategy | E11: 46078 | F11: 46082 | G11: 46101 | H11: 46117 | I11: 46122 | K11: 46143 | M11: 46162 | O11: 46183 | Q11: 46198 | S11: =IF(COUNTA(F11,H11,J11,L11,N11,P11,R11)=0,"Not Started",IF(R11<>"","In Production",IF(P11<>"","UAT Complete",IF(N11<>"","Visual Complete",IF(L11<>"","Pipeline Complete",IF(J11<>"","Data Model Complete",IF(H11<>"","Design Approved",IF(F11<>"","BRD Complete","Not Started")))))))) -> Design Approved | T11: =COUNTA(F11,H11,J11,L11,N11,P11,R11)/7 -> 0.28571429
B12: 6 | C12: Strategy — Initiatives Tracker | D12: Strategy | E12: 46082 | F12: 46091 | G12: 46113 | H12: 46127 | I12: 46137 | K12: 46157 | M12: 46178 | O12: 46193 | Q12: 46208 | S12: =IF(COUNTA(F12,H12,J12,L12,N12,P12,R12)=0,"Not Started",IF(R12<>"","In Production",IF(P12<>"","UAT Complete",IF(N12<>"","Visual Complete",IF(L12<>"","Pipeline Complete",IF(J12<>"","Data Model Complete",IF(H12<>"","Design Approved",IF(F12<>"","BRD Complete","Not Started")))))))) -> Design Approved | T12: =COUNTA(F12,H12,J12,L12,N12,P12,R12)/7 -> 0.28571429
B13: 7 | C13: Strategy — Performance vs Plan | D13: Strategy | E13: 46096 | F13: 46132 | G13: 46117 | I13: 46137 | K13: 46162 | M13: 46183 | O13: 46203 | Q13: 46218 | S13: =IF(COUNTA(F13,H13,J13,L13,N13,P13,R13)=0,"Not Started",IF(R13<>"","In Production",IF(P13<>"","UAT Complete",IF(N13<>"","Visual Complete",IF(L13<>"","Pipeline Complete",IF(J13<>"","Data Model Complete",IF(H13<>"","Design Approved",IF(F13<>"","BRD Complete","Not Started")))))))) -> BRD Complete | T13: =COUNTA(F13,H13,J13,L13,N13,P13,R13)/7 -> 0.14285714
B14: 8 | C14: Strategy — TBD #4 | D14: Strategy | S14: =IF(COUNTA(F14,H14,J14,L14,N14,P14,R14)=0,"Not Started",IF(R14<>"","In Production",IF(P14<>"","UAT Complete",IF(N14<>"","Visual Complete",IF(L14<>"","Pipeline Complete",IF(J14<>"","Data Model Complete",IF(H14<>"","Design Approved",IF(F14<>"","BRD Complete","Not Started")))))))) -> Not Started | T14: =COUNTA(F14,H14,J14,L14,N14,P14,R14)/7 -> 0
B15: 9 | C15: IT Tickets — SLA & Volume | D15: IT SM | E15: 46063 | F15: 46068 | G15: 46082 | H15: 46089 | I15: 46106 | J15: 46114 | K15: 46132 | L15: 46147 | M15: 46152 | O15: 46172 | Q15: 46188 | S15: =IF(COUNTA(F15,H15,J15,L15,N15,P15,R15)=0,"Not Started",IF(R15<>"","In Production",IF(P15<>"","UAT Complete",IF(N15<>"","Visual Complete",IF(L15<>"","Pipeline Complete",IF(J15<>"","Data Model Complete",IF(H15<>"","Design Approved",IF(F15<>"","BRD Complete","Not Started")))))))) -> Pipeline Complete | T15: =COUNTA(F15,H15,J15,L15,N15,P15,R15)/7 -> 0.57142857
B16: 10 | C16: IT Tickets — Backlog & Aging | D16: IT SM | E16: 46073 | F16: 46078 | G16: 46091 | H16: 46099 | I16: 46113 | J16: 46120 | K16: 46137 | L16: 46142 | M16: 46157 | O16: 46174 | Q16: 46188 | S16: =IF(COUNTA(F16,H16,J16,L16,N16,P16,R16)=0,"Not Started",IF(R16<>"","In Production",IF(P16<>"","UAT Complete",IF(N16<>"","Visual Complete",IF(L16<>"","Pipeline Complete",IF(J16<>"","Data Model Complete",IF(H16<>"","Design Approved",IF(F16<>"","BRD Complete","Not Started")))))))) -> Pipeline Complete | T16: =COUNTA(F16,H16,J16,L16,N16,P16,R16)/7 -> 0.57142857
B17: 11 | C17: HCM — Headcount & Movements | D17: HCM | E17: 46086 | F17: 46093 | G17: 46106 | H17: 46120 | I17: 46132 | K17: 46152 | M17: 46172 | O17: 46193 | Q17: 46208 | S17: =IF(COUNTA(F17,H17,J17,L17,N17,P17,R17)=0,"Not Started",IF(R17<>"","In Production",IF(P17<>"","UAT Complete",IF(N17<>"","Visual Complete",IF(L17<>"","Pipeline Complete",IF(J17<>"","Data Model Complete",IF(H17<>"","Design Approved",IF(F17<>"","BRD Complete","Not Started")))))))) -> Design Approved | T17: =COUNTA(F17,H17,J17,L17,N17,P17,R17)/7 -> 0.28571429
B18: 12 | C18: HCM — Attrition & Time-to-Hire | D18: HCM | E18: 46091 | F18: 46101 | G18: 46113 | I18: 46137 | K18: 46157 | M18: 46178 | O18: 46198 | Q18: 46213 | S18: =IF(COUNTA(F18,H18,J18,L18,N18,P18,R18)=0,"Not Started",IF(R18<>"","In Production",IF(P18<>"","UAT Complete",IF(N18<>"","Visual Complete",IF(L18<>"","Pipeline Complete",IF(J18<>"","Data Model Complete",IF(H18<>"","Design Approved",IF(F18<>"","BRD Complete","Not Started")))))))) -> BRD Complete | T18: =COUNTA(F18,H18,J18,L18,N18,P18,R18)/7 -> 0.14285714
B19: 13 | C19: TBD A | D19: TBD | S19: =IF(COUNTA(F19,H19,J19,L19,N19,P19,R19)=0,"Not Started",IF(R19<>"","In Production",IF(P19<>"","UAT Complete",IF(N19<>"","Visual Complete",IF(L19<>"","Pipeline Complete",IF(J19<>"","Data Model Complete",IF(H19<>"","Design Approved",IF(F19<>"","BRD Complete","Not Started")))))))) -> Not Started | T19: =COUNTA(F19,H19,J19,L19,N19,P19,R19)/7 -> 0
